<?xml version="1.0" encoding="utf-8"?>
<!-- This URDF was automatically created by SolidWorks to URDF Exporter! Originally created by Stephen Brawner (brawner@gmail.com) 
     Commit Version: 1.6.0-4-g7f85cfe  Build Version: 1.6.7995.38578
     For more information, please see http://wiki.ros.org/sw_urdf_exporter -->
<robot
  name="bexter_urdf_final_collisional">
  <link
    name="base_link">
    <inertial>
      <origin
        xyz="0.21925 -9.1394E-05 0.055722"
        rpy="0 0 0" />
      <mass
        value="40.988" />
      <inertia
        ixx="6.588"
        ixy="0.00031998"
        ixz="0.67196"
        iyy="3.043"
        iyz="-0.0002801"
        izz="7.9571" />
    </inertial>
    <visual>
      <origin
        xyz="0 0 0"
        rpy="0 0 0" />
      <geometry>
        <mesh
          filename="package://bexter_urdf_final_collisional/meshes/base_link.STL" />
      </geometry>
      <material
        name="">
        <color
          rgba="0.76078 0.4 0.18039 0.3" />
      </material>
    </visual>
    <collision>
      <origin
        xyz="0 0 0"
        rpy="0 0 0" />
      <geometry>
        <mesh
          filename="package://bexter_urdf_final_collisional/meshes/base_link.STL" />
      </geometry>
    </collision>
  </link>
  <link
    name="link_0">
    <inertial>
      <origin
        xyz="8.5418E-15 2.2204E-16 -0.023975"
        rpy="0 0 0" />
      <mass
        value="0.0603" />
      <inertia
        ixx="2.186E-05"
        ixy="3.0533E-21"
        ixz="4.4917E-21"
        iyy="1.7537E-05"
        iyz="1.3148E-20"
        izz="1.2483E-05" />
    </inertial>
    <visual>
      <origin
        xyz="0 0 0"
        rpy="0 0 0" />
      <geometry>
        <mesh
          filename="package://bexter_urdf_final_collisional/meshes/link_0.STL" />
      </geometry>
      <material
        name="">
        <color
          rgba="0.76078 0.4 0.18039 0.3" />
      </material>
    </visual>
    <collision>
      <origin
        xyz="0 0 0"
        rpy="0 0 0" />
      <geometry>
        <mesh
          filename="package://bexter_urdf_final_collisional/meshes/link_0.STL" />
      </geometry>
    </collision>
  </link>
  <joint
    name="joint_1"
    type="revolute">
    <origin
      xyz="0.026793 -0.1635 0.33675"
      rpy="0 0 0" />
    <parent
      link="base_link" />
    <child
      link="link_0" />
    <axis
      xyz="0 0 1" />
    <limit
      lower="-1.57"
      upper="1.57"
      effort="1.4"
      velocity="3.14" />
  </joint>
  <link
    name="link_1">
    <inertial>
      <origin
        xyz="-0.000344 -6.2E-05 -0.10869"
        rpy="0 0 0" />
      <mass
        value="0.52679" />
      <inertia
        ixx="0.0012889"
        ixy="2.862E-19"
        ixz="-1.5923E-05"
        iyy="0.0012889"
        iyz="-2.8417E-19"
        izz="0.00028669" />
    </inertial>
    <visual>
      <origin
        xyz="0 0 0"
        rpy="0 0 0" />
      <geometry>
        <mesh
          filename="package://bexter_urdf_final_collisional/meshes/link_1.STL" />
      </geometry>
      <material
        name="">
        <color
          rgba="0.76078 0.4 0.18039 0.3" />
      </material>
    </visual>
    <collision>
      <origin
        xyz="0 0 0"
        rpy="0 0 0" />
      <geometry>
        <mesh
          filename="package://bexter_urdf_final_collisional/meshes/link_1.STL" />
      </geometry>
    </collision>
  </link>
  <joint
    name="joint_2"
    type="continuous">
    <origin
      xyz="0 0 -0.0386"
      rpy="0 0 0" />
    <parent
      link="link_0" />
    <child
      link="link_1" />
    <axis
      xyz="0 1 0" />
    <limit
      lower="0"
      upper="0"
      effort="1.4"
      velocity="3.14" />
  </joint>
  <link
    name="link_2">
    <inertial>
      <origin
        xyz="0.10096 5.107E-15 -3.1E-05"
        rpy="0 0 0" />
      <mass
        value="0.51446" />
      <inertia
        ixx="0.00028708"
        ixy="2.2146E-18"
        ixz="3.3034E-18"
        iyy="0.0012672"
        iyz="1.786E-19"
        izz="0.0012754" />
    </inertial>
    <visual>
      <origin
        xyz="0 0 0"
        rpy="0 0 0" />
      <geometry>
        <mesh
          filename="package://bexter_urdf_final_collisional/meshes/link_2.STL" />
      </geometry>
      <material
        name="">
        <color
          rgba="0.76078 0.4 0.18039 0.3" />
      </material>
    </visual>
    <collision>
      <origin
        xyz="0 0 0"
        rpy="0 0 0" />
      <geometry>
        <mesh
          filename="package://bexter_urdf_final_collisional/meshes/link_2.STL" />
      </geometry>
    </collision>
  </link>
  <joint
    name="joint_3"
    type="revolute">
    <origin
      xyz="0 -6.2E-05 -0.2209"
      rpy="0 0 0" />
    <parent
      link="link_1" />
    <child
      link="link_2" />
    <axis
      xyz="0 -1 0" />
    <limit
      lower="-3.14"
      upper="1.57"
      effort="1.4"
      velocity="3.14" />
  </joint>
  <link
    name="end_effector">
    <inertial>
      <origin
        xyz="-0.019265 -0.018776 0.043874"
        rpy="0 0 0" />
      <mass
        value="0.16223" />
      <inertia
        ixx="0.00011342"
        ixy="-1.1141E-06"
        ixz="1.8045E-06"
        iyy="5.7717E-05"
        iyz="1.7943E-06"
        izz="0.00012647" />
    </inertial>
    <visual>
      <origin
        xyz="0 0 0"
        rpy="0 0 0" />
      <geometry>
        <mesh
          filename="package://bexter_urdf_final_collisional/meshes/end_effector.STL" />
      </geometry>
      <material
        name="">
        <color
          rgba="0.76078 0.4 0.18039 0.3" />
      </material>
    </visual>
    <collision>
      <origin
        xyz="0 0 0"
        rpy="0 0 0" />
      <geometry>
        <mesh
          filename="package://bexter_urdf_final_collisional/meshes/end_effector.STL" />
      </geometry>
    </collision>
  </link>
  <joint
    name="joint_end_effecot"
    type="fixed">
    <origin
      xyz="0.22568 0.022495 -0.04826"
      rpy="0 0 0" />
    <parent
      link="link_2" />
    <child
      link="end_effector" />
    <axis
      xyz="0 0 0" />
  </joint>
</robot>